2019-12-11 13:12:17,146 INFO: Microblog startup [inC:\Users\jackley\Python\Python37-32\hyperlinker\app\__init__.py:66]
2019-12-11 13:14:23,867 INFO: Microblog startup [inC:\Users\jackley\Python\Python37-32\hyperlinker\app\__init__.py:66]
2019-12-16 09:34:19,736 INFO: Microblog startup [inC:\Users\jackley\Python\Python37-32\hyperlinker\app\__init__.py:66]
2019-12-16 12:02:11,496 INFO: Microblog startup [inC:\Users\jackley\Python\Python37-32\hyperlinker\app\__init__.py:66]
2019-12-16 15:54:55,943 INFO: Microblog startup [inC:\Users\jackley\Python\Python37-32\hyperlinker\app\__init__.py:66]
2019-12-17 12:30:06,424 ERROR: Exception on /upload [POST] [inC:\Users\jackley\Python\Python37-32\venv\lib\site-packages\flask\app.py:1761]
Traceback (most recent call last):
  File "C:\Users\jackley\Python\Python37-32\venv\lib\site-packages\pandas\core\indexes\base.py", line 2657, in get_loc
    return self._engine.get_loc(key)
  File "pandas\_libs\index.pyx", line 108, in pandas._libs.index.IndexEngine.get_loc
  File "pandas\_libs\index.pyx", line 132, in pandas._libs.index.IndexEngine.get_loc
  File "pandas\_libs\hashtable_class_helper.pxi", line 1601, in pandas._libs.hashtable.PyObjectHashTable.get_item
  File "pandas\_libs\hashtable_class_helper.pxi", line 1608, in pandas._libs.hashtable.PyObjectHashTable.get_item
KeyError: 'id'

During handling of the above exception, another exception occurred:

Traceback (most recent call last):
  File "C:\Users\jackley\Python\Python37-32\venv\lib\site-packages\flask\app.py", line 2292, in wsgi_app
    response = self.full_dispatch_request()
  File "C:\Users\jackley\Python\Python37-32\venv\lib\site-packages\flask\app.py", line 1815, in full_dispatch_request
    rv = self.handle_user_exception(e)
  File "C:\Users\jackley\Python\Python37-32\venv\lib\site-packages\flask\app.py", line 1718, in handle_user_exception
    reraise(exc_type, exc_value, tb)
  File "C:\Users\jackley\Python\Python37-32\venv\lib\site-packages\flask\_compat.py", line 35, in reraise
    raise value
  File "C:\Users\jackley\Python\Python37-32\venv\lib\site-packages\flask\app.py", line 1813, in full_dispatch_request
    rv = self.dispatch_request()
  File "C:\Users\jackley\Python\Python37-32\venv\lib\site-packages\flask\app.py", line 1799, in dispatch_request
    return self.view_functions[rule.endpoint](**req.view_args)
  File "C:\Users\jackley\Python\Python37-32\hyperlinker\app\Hyperlink.py", line 63, in upload_hyperlink
    data_xls['Matter/Case ID#'] = data_xls['id'].astype(str)
  File "C:\Users\jackley\Python\Python37-32\venv\lib\site-packages\pandas\core\frame.py", line 2927, in __getitem__
    indexer = self.columns.get_loc(key)
  File "C:\Users\jackley\Python\Python37-32\venv\lib\site-packages\pandas\core\indexes\base.py", line 2659, in get_loc
    return self._engine.get_loc(self._maybe_cast_indexer(key))
  File "pandas\_libs\index.pyx", line 108, in pandas._libs.index.IndexEngine.get_loc
  File "pandas\_libs\index.pyx", line 132, in pandas._libs.index.IndexEngine.get_loc
  File "pandas\_libs\hashtable_class_helper.pxi", line 1601, in pandas._libs.hashtable.PyObjectHashTable.get_item
  File "pandas\_libs\hashtable_class_helper.pxi", line 1608, in pandas._libs.hashtable.PyObjectHashTable.get_item
KeyError: 'id'
2019-12-17 12:33:42,056 ERROR: Exception on /upload [POST] [inC:\Users\jackley\Python\Python37-32\venv\lib\site-packages\flask\app.py:1761]
Traceback (most recent call last):
  File "C:\Users\jackley\Python\Python37-32\venv\lib\site-packages\pandas\core\indexes\base.py", line 2657, in get_loc
    return self._engine.get_loc(key)
  File "pandas\_libs\index.pyx", line 108, in pandas._libs.index.IndexEngine.get_loc
  File "pandas\_libs\index.pyx", line 132, in pandas._libs.index.IndexEngine.get_loc
  File "pandas\_libs\hashtable_class_helper.pxi", line 1601, in pandas._libs.hashtable.PyObjectHashTable.get_item
  File "pandas\_libs\hashtable_class_helper.pxi", line 1608, in pandas._libs.hashtable.PyObjectHashTable.get_item
KeyError: 'id'

During handling of the above exception, another exception occurred:

Traceback (most recent call last):
  File "C:\Users\jackley\Python\Python37-32\venv\lib\site-packages\flask\app.py", line 2292, in wsgi_app
    response = self.full_dispatch_request()
  File "C:\Users\jackley\Python\Python37-32\venv\lib\site-packages\flask\app.py", line 1815, in full_dispatch_request
    rv = self.handle_user_exception(e)
  File "C:\Users\jackley\Python\Python37-32\venv\lib\site-packages\flask\app.py", line 1718, in handle_user_exception
    reraise(exc_type, exc_value, tb)
  File "C:\Users\jackley\Python\Python37-32\venv\lib\site-packages\flask\_compat.py", line 35, in reraise
    raise value
  File "C:\Users\jackley\Python\Python37-32\venv\lib\site-packages\flask\app.py", line 1813, in full_dispatch_request
    rv = self.dispatch_request()
  File "C:\Users\jackley\Python\Python37-32\venv\lib\site-packages\flask\app.py", line 1799, in dispatch_request
    return self.view_functions[rule.endpoint](**req.view_args)
  File "C:\Users\jackley\Python\Python37-32\hyperlinker\app\Hyperlink.py", line 63, in upload_hyperlink
    data_xls['Matter/Case ID#'] = data_xls['id'].astype(str)
  File "C:\Users\jackley\Python\Python37-32\venv\lib\site-packages\pandas\core\frame.py", line 2927, in __getitem__
    indexer = self.columns.get_loc(key)
  File "C:\Users\jackley\Python\Python37-32\venv\lib\site-packages\pandas\core\indexes\base.py", line 2659, in get_loc
    return self._engine.get_loc(self._maybe_cast_indexer(key))
  File "pandas\_libs\index.pyx", line 108, in pandas._libs.index.IndexEngine.get_loc
  File "pandas\_libs\index.pyx", line 132, in pandas._libs.index.IndexEngine.get_loc
  File "pandas\_libs\hashtable_class_helper.pxi", line 1601, in pandas._libs.hashtable.PyObjectHashTable.get_item
  File "pandas\_libs\hashtable_class_helper.pxi", line 1608, in pandas._libs.hashtable.PyObjectHashTable.get_item
KeyError: 'id'
2019-12-17 12:34:16,094 ERROR: Exception on /upload [POST] [inC:\Users\jackley\Python\Python37-32\venv\lib\site-packages\flask\app.py:1761]
Traceback (most recent call last):
  File "C:\Users\jackley\Python\Python37-32\venv\lib\site-packages\pandas\core\indexes\base.py", line 2657, in get_loc
    return self._engine.get_loc(key)
  File "pandas\_libs\index.pyx", line 108, in pandas._libs.index.IndexEngine.get_loc
  File "pandas\_libs\index.pyx", line 132, in pandas._libs.index.IndexEngine.get_loc
  File "pandas\_libs\hashtable_class_helper.pxi", line 1601, in pandas._libs.hashtable.PyObjectHashTable.get_item
  File "pandas\_libs\hashtable_class_helper.pxi", line 1608, in pandas._libs.hashtable.PyObjectHashTable.get_item
KeyError: 'id'

During handling of the above exception, another exception occurred:

Traceback (most recent call last):
  File "C:\Users\jackley\Python\Python37-32\venv\lib\site-packages\flask\app.py", line 2292, in wsgi_app
    response = self.full_dispatch_request()
  File "C:\Users\jackley\Python\Python37-32\venv\lib\site-packages\flask\app.py", line 1815, in full_dispatch_request
    rv = self.handle_user_exception(e)
  File "C:\Users\jackley\Python\Python37-32\venv\lib\site-packages\flask\app.py", line 1718, in handle_user_exception
    reraise(exc_type, exc_value, tb)
  File "C:\Users\jackley\Python\Python37-32\venv\lib\site-packages\flask\_compat.py", line 35, in reraise
    raise value
  File "C:\Users\jackley\Python\Python37-32\venv\lib\site-packages\flask\app.py", line 1813, in full_dispatch_request
    rv = self.dispatch_request()
  File "C:\Users\jackley\Python\Python37-32\venv\lib\site-packages\flask\app.py", line 1799, in dispatch_request
    return self.view_functions[rule.endpoint](**req.view_args)
  File "C:\Users\jackley\Python\Python37-32\hyperlinker\app\Hyperlink.py", line 63, in upload_hyperlink
    data_xls['Matter/Case ID#'] = data_xls['id'].astype(str)
  File "C:\Users\jackley\Python\Python37-32\venv\lib\site-packages\pandas\core\frame.py", line 2927, in __getitem__
    indexer = self.columns.get_loc(key)
  File "C:\Users\jackley\Python\Python37-32\venv\lib\site-packages\pandas\core\indexes\base.py", line 2659, in get_loc
    return self._engine.get_loc(self._maybe_cast_indexer(key))
  File "pandas\_libs\index.pyx", line 108, in pandas._libs.index.IndexEngine.get_loc
  File "pandas\_libs\index.pyx", line 132, in pandas._libs.index.IndexEngine.get_loc
  File "pandas\_libs\hashtable_class_helper.pxi", line 1601, in pandas._libs.hashtable.PyObjectHashTable.get_item
  File "pandas\_libs\hashtable_class_helper.pxi", line 1608, in pandas._libs.hashtable.PyObjectHashTable.get_item
KeyError: 'id'
2019-12-19 11:39:29,196 INFO: Microblog startup [inC:\Users\jackley\Python\Python37-32\hyperlinker\app\__init__.py:66]
2019-12-19 13:47:03,697 INFO: Microblog startup [inC:\Users\jackley\Python\Python37-32\hyperlinker\app\__init__.py:66]
2019-12-19 14:39:40,575 INFO: Microblog startup [inC:\Users\jackley\Python\Python37-32\hyperlinker\app\__init__.py:66]
2019-12-19 14:44:14,674 INFO: Microblog startup [inC:\Users\jackley\Python\Python37-32\hyperlinker\app\__init__.py:66]
2019-12-19 14:47:55,272 INFO: Microblog startup [inC:\Users\jackley\Python\Python37-32\hyperlinker\app\__init__.py:66]
