2019-11-26 11:51:06,838 ERROR: Exception on /upload [POST] [inC:\Users\jackley\Python\Python37-32\venv\lib\site-packages\flask\app.py:1761]
Traceback (most recent call last):
  File "C:\Users\jackley\Python\Python37-32\venv\lib\site-packages\pandas\core\indexes\base.py", line 2657, in get_loc
    return self._engine.get_loc(key)
  File "pandas\_libs\index.pyx", line 108, in pandas._libs.index.IndexEngine.get_loc
  File "pandas\_libs\index.pyx", line 132, in pandas._libs.index.IndexEngine.get_loc
  File "pandas\_libs\hashtable_class_helper.pxi", line 1601, in pandas._libs.hashtable.PyObjectHashTable.get_item
  File "pandas\_libs\hashtable_class_helper.pxi", line 1608, in pandas._libs.hashtable.PyObjectHashTable.get_item
KeyError: 'id'

During handling of the above exception, another exception occurred:

Traceback (most recent call last):
  File "C:\Users\jackley\Python\Python37-32\venv\lib\site-packages\flask\app.py", line 2292, in wsgi_app
    response = self.full_dispatch_request()
  File "C:\Users\jackley\Python\Python37-32\venv\lib\site-packages\flask\app.py", line 1815, in full_dispatch_request
    rv = self.handle_user_exception(e)
  File "C:\Users\jackley\Python\Python37-32\venv\lib\site-packages\flask\app.py", line 1718, in handle_user_exception
    reraise(exc_type, exc_value, tb)
  File "C:\Users\jackley\Python\Python37-32\venv\lib\site-packages\flask\_compat.py", line 35, in reraise
    raise value
  File "C:\Users\jackley\Python\Python37-32\venv\lib\site-packages\flask\app.py", line 1813, in full_dispatch_request
    rv = self.dispatch_request()
  File "C:\Users\jackley\Python\Python37-32\venv\lib\site-packages\flask\app.py", line 1799, in dispatch_request
    return self.view_functions[rule.endpoint](**req.view_args)
  File "C:\Users\jackley\Python\Python37-32\hyperlinker\app\Hyperlink.py", line 63, in upload_hyperlink
    data_xls['Matter/Case ID#'] = data_xls['id'].astype(str)
  File "C:\Users\jackley\Python\Python37-32\venv\lib\site-packages\pandas\core\frame.py", line 2927, in __getitem__
    indexer = self.columns.get_loc(key)
  File "C:\Users\jackley\Python\Python37-32\venv\lib\site-packages\pandas\core\indexes\base.py", line 2659, in get_loc
    return self._engine.get_loc(self._maybe_cast_indexer(key))
  File "pandas\_libs\index.pyx", line 108, in pandas._libs.index.IndexEngine.get_loc
  File "pandas\_libs\index.pyx", line 132, in pandas._libs.index.IndexEngine.get_loc
  File "pandas\_libs\hashtable_class_helper.pxi", line 1601, in pandas._libs.hashtable.PyObjectHashTable.get_item
  File "pandas\_libs\hashtable_class_helper.pxi", line 1608, in pandas._libs.hashtable.PyObjectHashTable.get_item
KeyError: 'id'
2019-11-27 14:18:24,433 INFO: Microblog startup [inC:\Users\jackley\Python\Python37-32\hyperlinker\app\__init__.py:66]
2019-12-02 14:32:27,264 ERROR: Exception on /hyperlinker [POST] [inC:\Users\jackley\Python\Python37-32\venv\lib\site-packages\flask\app.py:1761]
Traceback (most recent call last):
  File "C:\Users\jackley\Python\Python37-32\venv\lib\site-packages\pandas\core\internals\blocks.py", line 389, in fillna
    values, _ = self._try_coerce_args(self.values, value)
  File "C:\Users\jackley\Python\Python37-32\venv\lib\site-packages\pandas\core\internals\blocks.py", line 717, in _try_coerce_args
    type(self).__name__.lower().replace('Block', '')))
TypeError: cannot convert str to an floatblock

During handling of the above exception, another exception occurred:

Traceback (most recent call last):
  File "C:\Users\jackley\Python\Python37-32\venv\lib\site-packages\flask\app.py", line 2292, in wsgi_app
    response = self.full_dispatch_request()
  File "C:\Users\jackley\Python\Python37-32\venv\lib\site-packages\flask\app.py", line 1815, in full_dispatch_request
    rv = self.handle_user_exception(e)
  File "C:\Users\jackley\Python\Python37-32\venv\lib\site-packages\flask\app.py", line 1718, in handle_user_exception
    reraise(exc_type, exc_value, tb)
  File "C:\Users\jackley\Python\Python37-32\venv\lib\site-packages\flask\_compat.py", line 35, in reraise
    raise value
  File "C:\Users\jackley\Python\Python37-32\venv\lib\site-packages\flask\app.py", line 1813, in full_dispatch_request
    rv = self.dispatch_request()
  File "C:\Users\jackley\Python\Python37-32\venv\lib\site-packages\flask\app.py", line 1799, in dispatch_request
    return self.view_functions[rule.endpoint](**req.view_args)
  File "C:\Users\jackley\Python\Python37-32\hyperlinker\app\Hyperlink.py", line 22, in upload_hyperlink
    test.fillna('',inplace=True)
  File "C:\Users\jackley\Python\Python37-32\venv\lib\site-packages\pandas\core\frame.py", line 4034, in fillna
    downcast=downcast, **kwargs)
  File "C:\Users\jackley\Python\Python37-32\venv\lib\site-packages\pandas\core\generic.py", line 6123, in fillna
    downcast=downcast)
  File "C:\Users\jackley\Python\Python37-32\venv\lib\site-packages\pandas\core\internals\managers.py", line 525, in fillna
    return self.apply('fillna', **kwargs)
  File "C:\Users\jackley\Python\Python37-32\venv\lib\site-packages\pandas\core\internals\managers.py", line 395, in apply
    applied = getattr(b, f)(**kwargs)
  File "C:\Users\jackley\Python\Python37-32\venv\lib\site-packages\pandas\core\internals\blocks.py", line 412, in fillna
    return self.split_and_operate(mask, f, inplace)
  File "C:\Users\jackley\Python\Python37-32\venv\lib\site-packages\pandas\core\internals\blocks.py", line 468, in split_and_operate
    nv = f(m, v, i)
  File "C:\Users\jackley\Python\Python37-32\venv\lib\site-packages\pandas\core\internals\blocks.py", line 402, in f
    block = self.coerce_to_target_dtype(value)
  File "C:\Users\jackley\Python\Python37-32\venv\lib\site-packages\pandas\core\internals\blocks.py", line 1056, in coerce_to_target_dtype
    return self.astype(object)
  File "C:\Users\jackley\Python\Python37-32\venv\lib\site-packages\pandas\core\internals\blocks.py", line 534, in astype
    **kwargs)
  File "C:\Users\jackley\Python\Python37-32\venv\lib\site-packages\pandas\core\internals\blocks.py", line 633, in _astype
    values = astype_nansafe(values.ravel(), dtype, copy=True)
  File "C:\Users\jackley\Python\Python37-32\venv\lib\site-packages\pandas\core\dtypes\cast.py", line 702, in astype_nansafe
    return arr.astype(dtype, copy=True)
MemoryError
2019-12-04 15:52:48,868 INFO: Microblog startup [inC:\Users\jackley\Python\Python37-32\hyperlinker\app\__init__.py:66]
2019-12-04 15:54:53,465 INFO: Microblog startup [inC:\Users\jackley\Python\Python37-32\hyperlinker\app\__init__.py:66]
2019-12-06 09:34:14,822 ERROR: Exception on /upload [POST] [inC:\Users\jackley\Python\Python37-32\venv\lib\site-packages\flask\app.py:1761]
Traceback (most recent call last):
  File "C:\Users\jackley\Python\Python37-32\venv\lib\site-packages\pandas\core\indexes\base.py", line 2657, in get_loc
    return self._engine.get_loc(key)
  File "pandas\_libs\index.pyx", line 108, in pandas._libs.index.IndexEngine.get_loc
  File "pandas\_libs\index.pyx", line 132, in pandas._libs.index.IndexEngine.get_loc
  File "pandas\_libs\hashtable_class_helper.pxi", line 1601, in pandas._libs.hashtable.PyObjectHashTable.get_item
  File "pandas\_libs\hashtable_class_helper.pxi", line 1608, in pandas._libs.hashtable.PyObjectHashTable.get_item
KeyError: 'id'

During handling of the above exception, another exception occurred:

Traceback (most recent call last):
  File "C:\Users\jackley\Python\Python37-32\venv\lib\site-packages\flask\app.py", line 2292, in wsgi_app
    response = self.full_dispatch_request()
  File "C:\Users\jackley\Python\Python37-32\venv\lib\site-packages\flask\app.py", line 1815, in full_dispatch_request
    rv = self.handle_user_exception(e)
  File "C:\Users\jackley\Python\Python37-32\venv\lib\site-packages\flask\app.py", line 1718, in handle_user_exception
    reraise(exc_type, exc_value, tb)
  File "C:\Users\jackley\Python\Python37-32\venv\lib\site-packages\flask\_compat.py", line 35, in reraise
    raise value
  File "C:\Users\jackley\Python\Python37-32\venv\lib\site-packages\flask\app.py", line 1813, in full_dispatch_request
    rv = self.dispatch_request()
  File "C:\Users\jackley\Python\Python37-32\venv\lib\site-packages\flask\app.py", line 1799, in dispatch_request
    return self.view_functions[rule.endpoint](**req.view_args)
  File "C:\Users\jackley\Python\Python37-32\hyperlinker\app\Hyperlink.py", line 63, in upload_hyperlink
    data_xls['Matter/Case ID#'] = data_xls['id'].astype(str)
  File "C:\Users\jackley\Python\Python37-32\venv\lib\site-packages\pandas\core\frame.py", line 2927, in __getitem__
    indexer = self.columns.get_loc(key)
  File "C:\Users\jackley\Python\Python37-32\venv\lib\site-packages\pandas\core\indexes\base.py", line 2659, in get_loc
    return self._engine.get_loc(self._maybe_cast_indexer(key))
  File "pandas\_libs\index.pyx", line 108, in pandas._libs.index.IndexEngine.get_loc
  File "pandas\_libs\index.pyx", line 132, in pandas._libs.index.IndexEngine.get_loc
  File "pandas\_libs\hashtable_class_helper.pxi", line 1601, in pandas._libs.hashtable.PyObjectHashTable.get_item
  File "pandas\_libs\hashtable_class_helper.pxi", line 1608, in pandas._libs.hashtable.PyObjectHashTable.get_item
KeyError: 'id'
