2019-12-19 15:03:55,733 ERROR: Exception on /BoroughSplitter [POST] [inC:\Users\jackley\Python\Python37-32\venv\lib\site-packages\flask\app.py:1761]
Traceback (most recent call last):
  File "C:\Users\jackley\Python\Python37-32\venv\lib\site-packages\flask\app.py", line 2292, in wsgi_app
    response = self.full_dispatch_request()
  File "C:\Users\jackley\Python\Python37-32\venv\lib\site-packages\flask\app.py", line 1815, in full_dispatch_request
    rv = self.handle_user_exception(e)
  File "C:\Users\jackley\Python\Python37-32\venv\lib\site-packages\flask\app.py", line 1718, in handle_user_exception
    reraise(exc_type, exc_value, tb)
  File "C:\Users\jackley\Python\Python37-32\venv\lib\site-packages\flask\_compat.py", line 35, in reraise
    raise value
  File "C:\Users\jackley\Python\Python37-32\venv\lib\site-packages\flask\app.py", line 1813, in full_dispatch_request
    rv = self.dispatch_request()
  File "C:\Users\jackley\Python\Python37-32\venv\lib\site-packages\flask\app.py", line 1799, in dispatch_request
    return self.view_functions[rule.endpoint](**req.view_args)
  File "C:\Users\jackley\Python\Python37-32\hyperlinker\app\BoroughSplitter.py", line 34, in split_by_borough
    last7 = data_xls['Matter/Case ID#'].apply(lambda x: x[-7:])
  File "C:\Users\jackley\Python\Python37-32\venv\lib\site-packages\pandas\core\series.py", line 3591, in apply
    mapped = lib.map_infer(values, f, convert=convert_dtype)
  File "pandas\_libs\lib.pyx", line 2217, in pandas._libs.lib.map_infer
  File "C:\Users\jackley\Python\Python37-32\hyperlinker\app\BoroughSplitter.py", line 34, in <lambda>
    last7 = data_xls['Matter/Case ID#'].apply(lambda x: x[-7:])
TypeError: 'float' object is not subscriptable
2019-12-19 15:05:01,092 ERROR: Exception on /BoroughSplitter [POST] [inC:\Users\jackley\Python\Python37-32\venv\lib\site-packages\flask\app.py:1761]
Traceback (most recent call last):
  File "C:\Users\jackley\Python\Python37-32\venv\lib\site-packages\pandas\core\indexes\base.py", line 2657, in get_loc
    return self._engine.get_loc(key)
  File "pandas\_libs\index.pyx", line 108, in pandas._libs.index.IndexEngine.get_loc
  File "pandas\_libs\index.pyx", line 132, in pandas._libs.index.IndexEngine.get_loc
  File "pandas\_libs\hashtable_class_helper.pxi", line 1601, in pandas._libs.hashtable.PyObjectHashTable.get_item
  File "pandas\_libs\hashtable_class_helper.pxi", line 1608, in pandas._libs.hashtable.PyObjectHashTable.get_item
KeyError: 'id'

During handling of the above exception, another exception occurred:

Traceback (most recent call last):
  File "C:\Users\jackley\Python\Python37-32\venv\lib\site-packages\flask\app.py", line 2292, in wsgi_app
    response = self.full_dispatch_request()
  File "C:\Users\jackley\Python\Python37-32\venv\lib\site-packages\flask\app.py", line 1815, in full_dispatch_request
    rv = self.handle_user_exception(e)
  File "C:\Users\jackley\Python\Python37-32\venv\lib\site-packages\flask\app.py", line 1718, in handle_user_exception
    reraise(exc_type, exc_value, tb)
  File "C:\Users\jackley\Python\Python37-32\venv\lib\site-packages\flask\_compat.py", line 35, in reraise
    raise value
  File "C:\Users\jackley\Python\Python37-32\venv\lib\site-packages\flask\app.py", line 1813, in full_dispatch_request
    rv = self.dispatch_request()
  File "C:\Users\jackley\Python\Python37-32\venv\lib\site-packages\flask\app.py", line 1799, in dispatch_request
    return self.view_functions[rule.endpoint](**req.view_args)
  File "C:\Users\jackley\Python\Python37-32\hyperlinker\app\BoroughSplitter.py", line 30, in split_by_borough
    data_xls['Matter/Case ID#'] = data_xls['id'].astype(str)
  File "C:\Users\jackley\Python\Python37-32\venv\lib\site-packages\pandas\core\frame.py", line 2927, in __getitem__
    indexer = self.columns.get_loc(key)
  File "C:\Users\jackley\Python\Python37-32\venv\lib\site-packages\pandas\core\indexes\base.py", line 2659, in get_loc
    return self._engine.get_loc(self._maybe_cast_indexer(key))
  File "pandas\_libs\index.pyx", line 108, in pandas._libs.index.IndexEngine.get_loc
  File "pandas\_libs\index.pyx", line 132, in pandas._libs.index.IndexEngine.get_loc
  File "pandas\_libs\hashtable_class_helper.pxi", line 1601, in pandas._libs.hashtable.PyObjectHashTable.get_item
  File "pandas\_libs\hashtable_class_helper.pxi", line 1608, in pandas._libs.hashtable.PyObjectHashTable.get_item
KeyError: 'id'
2019-12-19 15:06:39,553 ERROR: Exception on /BoroughSplitter [POST] [inC:\Users\jackley\Python\Python37-32\venv\lib\site-packages\flask\app.py:1761]
Traceback (most recent call last):
  File "C:\Users\jackley\Python\Python37-32\venv\lib\site-packages\pandas\core\indexes\base.py", line 2657, in get_loc
    return self._engine.get_loc(key)
  File "pandas\_libs\index.pyx", line 108, in pandas._libs.index.IndexEngine.get_loc
  File "pandas\_libs\index.pyx", line 132, in pandas._libs.index.IndexEngine.get_loc
  File "pandas\_libs\hashtable_class_helper.pxi", line 1601, in pandas._libs.hashtable.PyObjectHashTable.get_item
  File "pandas\_libs\hashtable_class_helper.pxi", line 1608, in pandas._libs.hashtable.PyObjectHashTable.get_item
KeyError: 'id'

During handling of the above exception, another exception occurred:

Traceback (most recent call last):
  File "C:\Users\jackley\Python\Python37-32\venv\lib\site-packages\flask\app.py", line 2292, in wsgi_app
    response = self.full_dispatch_request()
  File "C:\Users\jackley\Python\Python37-32\venv\lib\site-packages\flask\app.py", line 1815, in full_dispatch_request
    rv = self.handle_user_exception(e)
  File "C:\Users\jackley\Python\Python37-32\venv\lib\site-packages\flask\app.py", line 1718, in handle_user_exception
    reraise(exc_type, exc_value, tb)
  File "C:\Users\jackley\Python\Python37-32\venv\lib\site-packages\flask\_compat.py", line 35, in reraise
    raise value
  File "C:\Users\jackley\Python\Python37-32\venv\lib\site-packages\flask\app.py", line 1813, in full_dispatch_request
    rv = self.dispatch_request()
  File "C:\Users\jackley\Python\Python37-32\venv\lib\site-packages\flask\app.py", line 1799, in dispatch_request
    return self.view_functions[rule.endpoint](**req.view_args)
  File "C:\Users\jackley\Python\Python37-32\hyperlinker\app\BoroughSplitter.py", line 30, in split_by_borough
    data_xls['Matter/Case ID#'] = data_xls['id'].astype(str)
  File "C:\Users\jackley\Python\Python37-32\venv\lib\site-packages\pandas\core\frame.py", line 2927, in __getitem__
    indexer = self.columns.get_loc(key)
  File "C:\Users\jackley\Python\Python37-32\venv\lib\site-packages\pandas\core\indexes\base.py", line 2659, in get_loc
    return self._engine.get_loc(self._maybe_cast_indexer(key))
  File "pandas\_libs\index.pyx", line 108, in pandas._libs.index.IndexEngine.get_loc
  File "pandas\_libs\index.pyx", line 132, in pandas._libs.index.IndexEngine.get_loc
  File "pandas\_libs\hashtable_class_helper.pxi", line 1601, in pandas._libs.hashtable.PyObjectHashTable.get_item
  File "pandas\_libs\hashtable_class_helper.pxi", line 1608, in pandas._libs.hashtable.PyObjectHashTable.get_item
KeyError: 'id'
2019-12-19 15:08:28,985 ERROR: Exception on /BoroughSplitter [POST] [inC:\Users\jackley\Python\Python37-32\venv\lib\site-packages\flask\app.py:1761]
Traceback (most recent call last):
  File "C:\Users\jackley\Python\Python37-32\venv\lib\site-packages\pandas\core\indexes\base.py", line 2657, in get_loc
    return self._engine.get_loc(key)
  File "pandas\_libs\index.pyx", line 108, in pandas._libs.index.IndexEngine.get_loc
  File "pandas\_libs\index.pyx", line 132, in pandas._libs.index.IndexEngine.get_loc
  File "pandas\_libs\hashtable_class_helper.pxi", line 1601, in pandas._libs.hashtable.PyObjectHashTable.get_item
  File "pandas\_libs\hashtable_class_helper.pxi", line 1608, in pandas._libs.hashtable.PyObjectHashTable.get_item
KeyError: 'id'

During handling of the above exception, another exception occurred:

Traceback (most recent call last):
  File "C:\Users\jackley\Python\Python37-32\venv\lib\site-packages\flask\app.py", line 2292, in wsgi_app
    response = self.full_dispatch_request()
  File "C:\Users\jackley\Python\Python37-32\venv\lib\site-packages\flask\app.py", line 1815, in full_dispatch_request
    rv = self.handle_user_exception(e)
  File "C:\Users\jackley\Python\Python37-32\venv\lib\site-packages\flask\app.py", line 1718, in handle_user_exception
    reraise(exc_type, exc_value, tb)
  File "C:\Users\jackley\Python\Python37-32\venv\lib\site-packages\flask\_compat.py", line 35, in reraise
    raise value
  File "C:\Users\jackley\Python\Python37-32\venv\lib\site-packages\flask\app.py", line 1813, in full_dispatch_request
    rv = self.dispatch_request()
  File "C:\Users\jackley\Python\Python37-32\venv\lib\site-packages\flask\app.py", line 1799, in dispatch_request
    return self.view_functions[rule.endpoint](**req.view_args)
  File "C:\Users\jackley\Python\Python37-32\hyperlinker\app\BoroughSplitter.py", line 30, in split_by_borough
    data_xls['Matter/Case ID#'] = data_xls['id'].astype(str)
  File "C:\Users\jackley\Python\Python37-32\venv\lib\site-packages\pandas\core\frame.py", line 2927, in __getitem__
    indexer = self.columns.get_loc(key)
  File "C:\Users\jackley\Python\Python37-32\venv\lib\site-packages\pandas\core\indexes\base.py", line 2659, in get_loc
    return self._engine.get_loc(self._maybe_cast_indexer(key))
  File "pandas\_libs\index.pyx", line 108, in pandas._libs.index.IndexEngine.get_loc
  File "pandas\_libs\index.pyx", line 132, in pandas._libs.index.IndexEngine.get_loc
  File "pandas\_libs\hashtable_class_helper.pxi", line 1601, in pandas._libs.hashtable.PyObjectHashTable.get_item
  File "pandas\_libs\hashtable_class_helper.pxi", line 1608, in pandas._libs.hashtable.PyObjectHashTable.get_item
KeyError: 'id'
